<robot name="snake_robot">
  <link name="link1" />
  <link name="link2" />
  <link name="link3" />
  <link name="link4" />
  <link name="link5" />
  <link name="link6" />
  <link name="link7" />
  <link name="link8" />
  <link name="link9" />
  <link name="link10" />
  <link name="link11" />
  <link name="link12" />


  <joint name="joint1" type="prismatic">
    <parent link="link1"/>
    <child link="link2"/>
    <origin xyz="0 0 0" rpy="0 0 0" />
    <axis xyz="1 0 0" />
  </joint>

  <joint name="joint2" type="prismatic">
    <parent link="link2"/>
    <child link="link3"/>
    <origin xyz="0 0 0" rpy="0 0 0" />
    <axis xyz="0 1 0" />
  </joint>

  <joint name="joint3" type="revolute">
    <parent link="link3"/>
    <child link="link4"/>
    <origin xyz="0 0 0" rpy="0 0 0" />
    <axis xyz="0 0 1" />
  </joint>

  <joint name="joint4" type="revolute">
    <parent link="link4"/>
    <child link="link5"/>
    <origin xyz="2 0 0" rpy="0 0 0" />
    <axis xyz="0 0 1" />
  </joint>

  <joint name="joint5" type="revolute">
    <parent link="link5"/>
    <child link="link6"/>
    <origin xyz="0 2 0" rpy="0 0 0" />
    <axis xyz="0 0 1" />
  </joint>

  <joint name="joint6" type="revolute">
    <parent link="link6"/>
    <child link="link7"/>
    <origin xyz="2 0 0" rpy="0 0 0" />
    <axis xyz="0 0 1" />
  </joint>

  <joint name="joint7" type="revolute">
    <parent link="link7"/>
    <child link="link8"/>
    <origin xyz="0 2 0" rpy="0 0 0" />
    <axis xyz="0 0 1" />
  </joint>

    <joint name="joint8" type="revolute">
    <parent link="link8"/>
    <child link="link9"/>
    <origin xyz="2 0 0" rpy="0 0 0" />
    <axis xyz="0 0 1" />
  </joint>

  <joint name="joint9" type="revolute">
    <parent link="link9"/>
    <child link="link10"/>
    <origin xyz="0 2 0" rpy="0 0 0" />
    <axis xyz="0 0 1" />
  </joint>

  <joint name="joint10" type="revolute">
    <parent link="link10"/>
    <child link="link11"/>
    <origin xyz="2 0 0" rpy="0 0 0" />
    <axis xyz="0 0 1" />
  </joint>

  <joint name="joint11" type="fixed">
    <parent link="link11"/>
    <child link="link12"/>
    <origin xyz="0 2 0" rpy="0 0 0" />
    <axis xyz="0 0 1" />
  </joint>
</robot>

